<?xml version="1.0"?>
<robot xmlns:xacro="http://www.ros.org/wiki/xacro">

	<!-- import gazebo files -->
	<xacro:include filename="$(find hir_description)/urdf/manipulator/manipulator.gazebo.xacro" />

	<!-- import transmission -->
	<xacro:include filename="$(find hir_description)/urdf/manipulator/manipulator.transmission.xacro" />

  
  <!-- joint 0 -->
  <joint name="shoulder_slider" type="fixed">
    <!-- <origin xyz="0.01 0 0.79" rpy="0 0 -1.5707"/> -->
	<origin xyz="0.01 0 0.9" rpy="0 0 -1.5707" />
    <parent link="base_link"/>
    <child link="shoulder_link"/>
    <axis xyz="0 0 1"/>
    <limit effort="1000" lower="0" upper="0.4" velocity="1.0"/>
  </joint>

  <link name="shoulder_link">
    <inertial>
      <mass value="0.5"/>
      <origin xyz="0 0 0"/>
      <inertia ixx="1.0" ixy="0.0" ixz="0.0" iyy="1.0" iyz="0.0" izz="1.0"/>
    </inertial>
    <visual>
      <origin xyz="0 0.035 0" rpy="1.5707 0 3.1415"/>
      <geometry>
		<mesh filename="package://hir_description/meshes/STL/joint0.stl" />
      </geometry>
      <material name="blue">
        <color rgba="0 0 .8 1"/>
      </material>
    </visual>
    <collision>
      <origin xyz="0 0.035 0" rpy="1.5707 0 3.1415"/>
      <geometry>
        <box size="0.0330 0.28 0.0320"/>
      </geometry>
    </collision>
  </link>

  <!-- joint 1 -->
  <joint name="shoulder_roll_joint" type="fixed">
    <origin xyz="0 0.1 0.03" rpy="0 0 0"/>
    <parent link="shoulder_link"/>
    <child link="shoulder_roll_link"/>
    <axis xyz="0 1 0"/> 
    <limit lower="-1" upper="1" effort="30" velocity="1.571"/>
  </joint>

  <link name="shoulder_roll_link">
    <inertial>
      <mass value="0.5"/>
      <origin xyz="0 0 0"/>
      <inertia ixx="1.0" ixy="0.0" ixz="0.0" iyy="1.0" iyz="0.0" izz="1.0"/>
    </inertial>
    <visual>
      <origin xyz="0 0 0" rpy="1.5707 1.5707 0"/>
      <geometry>
		<mesh filename="package://hir_description/meshes/STL/joint1.stl" />
      </geometry>
      <material name="green"/>
    </visual>
    <collision>
      <origin xyz="0 0 0" rpy="1.5707 1.5707 0"/>
      <geometry>
        <box size="0.0330 0.05 0.0320"/>
      </geometry>
    </collision>
  </link>

  <!-- joint 2 -->
  <joint name="shoulder_pitch_joint" type="revolute">
    <origin xyz="0 0.04 0" rpy="0 0 0"/>
    <parent link="shoulder_roll_link"/>
    <child link="shoulder_pitch_link"/>
    <axis xyz="1.0 0.001 0.0"/> 
    <limit lower="0" upper="3.14" effort="30" velocity="1.571"/>
  </joint>

  <link name="shoulder_pitch_link">
    <inertial>
      <mass value="0.5"/>
      <origin xyz="0 0 0"/>
      <inertia ixx="1.0" ixy="0.0" ixz="0.0" iyy="1.0" iyz="0.0" izz="1.0"/>
    </inertial>
    <visual>
      <origin xyz="0 0 -0.1" rpy="3.1415 0 1.5707"/>
      <geometry>
		<mesh filename="package://hir_description/meshes/STL/joint2.stl" />
      </geometry>
      <material name="red"/>
    </visual>
    <collision>
      <origin xyz="0 0 -0.1" rpy="3.1415 0 1.5707"/>
      <geometry>
        <box size="0.0330 0.0320 0.180"/>
      </geometry>
    </collision>
  </link>

  <!-- joint 3 -->
  <joint name="elbow_pitch_joint" type="revolute">
    <origin xyz="0 0.001 -0.224" rpy="0 0 0"/>
    <parent link="shoulder_pitch_link"/>
    <child link="elbow_pitch_link"/>
    <axis xyz="1 0 0"/> 
    <limit lower="0" upper="3.0" effort="30" velocity="1.571"/>
  </joint>

  <link name="elbow_pitch_link">
    <inertial>
      <mass value="0.5"/>
      <origin xyz="0 0 0"/>
      <inertia ixx="1.0" ixy="0.0" ixz="0.0" iyy="1.0" iyz="0.0" izz="1.0"/>
    </inertial>
    <visual>
      <origin xyz=" 0 -0.035 -0.12 " rpy="3.1415 0 -1.5707"/>
      <geometry>
		<mesh filename="package://hir_description/meshes/STL/joint3.stl" />
	  </geometry>
      <material name="blue"/>
    </visual>
    <collision>
      <origin xyz=" 0 -0.035 -0.12 " rpy="3.1415 0 -1.5707"/>
      <geometry>
        <box size="0.0330 0.0320 0.180"/>
      </geometry>
    </collision>
  </link>

  <!-- joint 4 -->
  <joint name="wrist_pitch_joint" type="revolute">
    <origin xyz="0 -0.04 -0.239" rpy="0 0 0"/>
    <parent link="elbow_pitch_link"/>
    <child link="wrist_pitch_link"/>
    <axis xyz="1.0 0.001 0.0"/> 
    <limit lower="-1.57" upper="1.57" effort="30" velocity="1.571"/>
  </joint>

  <link name="wrist_pitch_link">
    <inertial>
      <mass value="0.5"/>
      <origin xyz="0 0 0"/>
      <inertia ixx="1.0" ixy="0.0" ixz="0.0" iyy="1.0" iyz="0.0" izz="1.0"/>
    </inertial>
    <visual>
      <origin xyz=" 0 0 -0.026 " rpy="0 0 0"/>
      <geometry>
		<mesh filename="package://hir_description/meshes/STL/joint4.stl" />
	  </geometry>
      <material name="green"/>
    </visual>
    <collision>
      <origin xyz=" 0 0 -0.026 " rpy="0 0 0"/>
      <geometry>
        <box size="0.0330 0.0320 0.0320"/>
      </geometry>
    </collision>
  </link>

  <!-- joint 5 -->
  <joint name="wrist_yaw_joint" type="revolute">
    <origin xyz="0 0 -0.0525" rpy="0 0 0"/>
    <parent link="wrist_pitch_link"/>
    <child link="wrist_yaw_link"/>
    <axis xyz="0 1 0"/> 
    <limit lower="-1.57" upper="1.57" effort="30" velocity="1.571"/>
  </joint>

  <link name="wrist_yaw_link">
    <inertial>
      <mass value="0.5"/>
      <origin xyz="0 0 0"/>
      <inertia ixx="1.0" ixy="0.0" ixz="0.0" iyy="1.0" iyz="0.0" izz="1.0"/>
    </inertial>
    <visual>
      <origin xyz="0 0 -0.016" rpy="-1.5707 0 0"/>
      <geometry>
		<mesh filename="package://hir_description/meshes/STL/joint5.stl"/>
	  </geometry>
      <material name="red"/>
    </visual>
    <collision>
      <origin xyz="0 0 -0.016" rpy="-1.5707 0 0"/>
      <geometry>
        <box size="0.0330 0.0320 0.0320"/>
      </geometry>
    </collision>
  </link>

  <!--joint 6 + hand -->
  <joint name="wrist_roll_joint" type="fixed">
    <origin xyz="0 0 -0.05" rpy="0 0 0"/>
    <parent link="wrist_yaw_link"/>
    <child link="wrist_roll_link"/>
    <axis xyz="0 0.01 1.0"/> 
    <limit lower="-1.57" upper="1.57" effort="30" velocity="1.571"/>
  </joint>

  <link name="wrist_roll_link">
    <inertial>
      <mass value="0.5"/>
      <origin xyz="0 0 0"/>
      <inertia ixx="1.0" ixy="0.0" ixz="0.0" iyy="1.0" iyz="0.0" izz="1.0"/>
    </inertial>
    <visual>
      <origin xyz="0 0 -0.075" rpy="0 0 0"/>
      <geometry>
		<mesh filename="package://hir_description/meshes/STL/joint6.stl" />
	  </geometry>
      <material name="blue"/>
    </visual>
    <collision>
      <origin xyz="0 0 -0.075" rpy="0 0 0"/>
      <geometry>
        <box size="0.0330 0.0320 0.0320"/>
      </geometry>
    </collision>
  </link>

</robot>
